Workbook
Name Import1_FuelChain_COL: #REF!
Name Import1_Impact_COL: #REF!
Name Import1_Region_COL: #REF!
Name Import1_Scenario_COL: #REF!
Name Import1_Sensitivity_COL: #REF!
Name Import1_Substage_COL: #REF!
Name l_ElecFuelChain: #REF!
Name n_SelectedImpact_Elec: 'Mix électriques'!$C$13
Name n_SelectedRegion_Elec: 'Mix électriques'!$C$17
Name n_SelectedScenario_Elec: 'Mix électriques'!$C$14
Name n_SelectedSensitivity_Elec: 'Mix électriques'!$C$15

Sheet Information
B2: Feuille | C2: Contenu
B3: Inventaire | C3: Contient les données d'ACV pour mener le calcul d'évaluation d'impact
B4: Analyse d'impacts | C4: Comparaison de l'impact des deux véhicules
B5: Composition voiture | C5: Information sur la composition d'un véhicule
B6: Production batterie | C6: Information sur la production et la fin de vie d'une batterie de véhicule électrique
B7: Mix électriques | C7: Composition des mix électriques
B8: Carburant | C8: Demande en énergie et émissions due à la production du carburant

Sheet Inventaire
B2: PARAMÈTRES
D3: nom | E3: unité | F3: quantité | I3: Étapes
B4: Paramètres véhicules | D4: Durée de vie | E4: km | F4: 250000 | I4: 1 | J4: Durée de vie de la voiture
D5: Kilométrage annuel | E5: km/an | F5: 15000 | I5: 2 | J5: Émissions de CO2 du diesel
D6: Durée de vie | E6: ans | G6: 1 | I6: 3 | J6: Composition d'une voiture
D7: Consommation diesel | E7: l/100 km | F7: 6 | I7: 4 | J7: Composition du mix
D8: Consommation électrique | E8: kWh/100 km | F8: 18 | I8: 5 | J8: Calcul des impacts caractérisés
D9: Pertes de distribution et de chargement (électricité) | E9: % | F9: 0.1
D10: Masse d'une voiture thermique | E10: kg | F10: 1700
D11: Masse d'une voiture électrique (hors batterie) | E11: kg | F11: 1600
D12: Capacité de la batterie | E12: kWh | F12: 60
D13: Maintenance annuelle | E13: h | F13: 100
B15: Paramètres combustion | D15: Formule moyenne du gazole routier | F15: C12H24
D16: Masse molaire du carbone | E16: g/mol | F16: 12
D17: Masse molaire de l'hydrogène | E17: g/mol | F17: 1
D18: Masse molaire de l'oxygène | E18: g/mol | F18: 16
D19: Réaction de combustion complète (à équilibrer !) | F19: C12H24 + O2 = CO2 + H2O
D20: Densité massique du gazole | E20: kg/l | F20: 0.85
D21: Densité énergétique du gazole | E21: MJ/l | F21: 42
D22: Émissions dues à la combustion d'un litre de gazole | E22: kg CO2 | G22: 2
B27: MATRICES ACV (DONNÉES D'ENTRÉE)
F29: transport, voiture diesel | G29: transport, voiture électrique | H29: voiture diesel | I29: voiture électrique | J29: batterie lithium-ion, production | K29: batterie lithium-ion, recyclage | L29: gazole | M29: maintenance | N29: acier | O29: fonte | P29: aluminium | Q29: verre | R29: peinture | S29: plastiques | T29: gomme | U29: lubrifiant | V29: cuivre | W29: métaux non ferreux | X29: électronique | Y29: textiles | Z29: fibre de carbone | AA29: électricité du réseau, Allemagne | AB29: électricité du réseau, France | AC29: électricité nucléaire | AD29: électricité éolienne | AE29: électricité photovoltaïque | AF29: électricité hydroélectrique | AG29: électricité au charbon | AH29: électricité au gaz | AI29: électricité, autre | AJ29: gaz naturel | AK29: chaleur
B30: A (activités) | D30: activité | E30: unité | F30: km | G30: km | H30: u | I30: u | J30: kWh | K30: kWh | L30: l | M30: h | N30: kg | O30: kg | P30: kg | Q30: kg | R30: kg | S30: kg | T30: kg | U30: kg | V30: kg | W30: kg | X30: kg | Y30: kg | Z30: kg | AA30: kWh | AB30: kWh | AC30: kWh | AD30: kWh | AE30: kWh | AF30: kWh | AG30: kWh | AH30: kWh | AI30: kWh | AJ30: MJ | AK30: MJ
D31: transport, voiture diesel | E31: km | F31: 0 | G31: 0 | H31: 0 | I31: 0 | J31: 0 | K31: 0 | L31: 0 | M31: 0 | N31: 0 | O31: 0 | P31: 0 | Q31: 0 | R31: 0 | S31: 0 | T31: 0 | U31: 0 | V31: 0 | W31: 0 | X31: 0 | Y31: 0 | Z31: 0 | AA31: 0 | AB31: 0 | AC31: 0 | AD31: 0 | AE31: 0 | AF31: 0 | AG31: 0 | AH31: 0 | AI31: 0 | AJ31: 0 | AK31: 0
D32: transport, voiture électrique | E32: km | F32: 0 | G32: 0 | H32: 0 | I32: 0 | J32: 0 | K32: 0 | L32: 0 | M32: 0 | N32: 0 | O32: 0 | P32: 0 | Q32: 0 | R32: 0 | S32: 0 | T32: 0 | U32: 0 | V32: 0 | W32: 0 | X32: 0 | Y32: 0 | Z32: 0 | AA32: 0 | AB32: 0 | AC32: 0 | AD32: 0 | AE32: 0 | AF32: 0 | AG32: 0 | AH32: 0 | AI32: 0 | AJ32: 0 | AK32: 0
D33: voiture diesel | E33: u | F33: =1/$F$4 -> 4e-06 | G33: 0 | H33: 0 | I33: 0 | J33: 0 | K33: 0 | L33: 0 | M33: 0 | N33: 0 | O33: 0 | P33: 0 | Q33: 0 | R33: 0 | S33: 0 | T33: 0 | U33: 0 | V33: 0 | W33: 0 | X33: 0 | Y33: 0 | Z33: 0 | AA33: 0 | AB33: 0 | AC33: 0 | AD33: 0 | AE33: 0 | AF33: 0 | AG33: 0 | AH33: 0 | AI33: 0 | AJ33: 0 | AK33: 0
D34: voiture électrique | E34: u | F34: 0 | G34: =1/$F$4 -> 4e-06 | H34: 0 | I34: 0 | J34: 0 | K34: 0 | L34: 0 | M34: 0 | N34: 0 | O34: 0 | P34: 0 | Q34: 0 | R34: 0 | S34: 0 | T34: 0 | U34: 0 | V34: 0 | W34: 0 | X34: 0 | Y34: 0 | Z34: 0 | AA34: 0 | AB34: 0 | AC34: 0 | AD34: 0 | AE34: 0 | AF34: 0 | AG34: 0 | AH34: 0 | AI34: 0 | AJ34: 0 | AK34: 0
D35: batterie lithium-ion, production | E35: kWh | F35: 0 | G35: {=F12/F4} -> 0.00024 | H35: 0 | I35: 0 | J35: 0 | K35: 0 | L35: 0 | M35: 0 | N35: 0 | O35: 0 | P35: 0 | Q35: 0 | R35: 0 | S35: 0 | T35: 0 | U35: 0 | V35: 0 | W35: 0 | X35: 0 | Y35: 0 | Z35: 0 | AA35: 0 | AB35: 0 | AC35: 0 | AD35: 0 | AE35: 0 | AF35: 0 | AG35: 0 | AH35: 0 | AI35: 0 | AJ35: 0 | AK35: 0
D36: batterie lithium-ion, recyclage | E36: kWh | F36: 0 | G36: =F12/F4 -> 0.00024 | H36: 0 | I36: 0 | J36: 0 | K36: 0 | L36: 0 | M36: 0 | N36: 0 | O36: 0 | P36: 0 | Q36: 0 | R36: 0 | S36: 0 | T36: 0 | U36: 0 | V36: 0 | W36: 0 | X36: 0 | Y36: 0 | Z36: 0 | AA36: 0 | AB36: 0 | AC36: 0 | AD36: 0 | AE36: 0 | AF36: 0 | AG36: 0 | AH36: 0 | AI36: 0 | AJ36: 0 | AK36: 0
D37: gazole | E37: l | F37: =F7/100 -> 0.06 | G37: 0 | H37: 0 | I37: 0 | J37: 0 | K37: 0 | L37: 0 | M37: 0 | N37: 0 | O37: 0 | P37: 0 | Q37: 0 | R37: 0 | S37: 0 | T37: 0 | U37: 0 | V37: 0 | W37: 0 | X37: 0 | Y37: 0 | Z37: 0 | AA37: 0 | AB37: 0 | AC37: 0 | AD37: 0 | AE37: 0 | AF37: 0 | AG37: 0 | AH37: 0 | AI37: 0 | AJ37: 0 | AK37: 0
D38: maintenance | E38: h | F38: =1/(F6*F13) -> #DIV/0! | G38: 0 | H38: 0 | I38: 0 | J38: 0 | K38: 0 | L38: 0 | M38: 0 | N38: 0 | O38: 0 | P38: 0 | Q38: 0 | R38: 0 | S38: 0 | T38: 0 | U38: 0 | V38: 0 | W38: 0 | X38: 0 | Y38: 0 | Z38: 0 | AA38: 0 | AB38: 0 | AC38: 0 | AD38: 0 | AE38: 0 | AF38: 0 | AG38: 0 | AH38: 0 | AI38: 0 | AJ38: 0 | AK38: 0
D39: acier | E39: kg | F39: 0 | G39: 0 | J39: 0.1 | K39: 0 | L39: 0 | M39: 0 | N39: 0 | O39: 0 | P39: 0 | Q39: 0 | R39: 0 | S39: 0 | T39: 0 | U39: 0 | V39: 0 | W39: 0 | X39: 0 | Y39: 0 | Z39: 0 | AA39: 0 | AB39: 0 | AC39: 0 | AD39: 0 | AE39: 0 | AF39: 0 | AG39: 0 | AH39: 0 | AI39: 0 | AJ39: 0 | AK39: 0
D40: fonte | E40: kg | F40: 0 | G40: 0 | J40: 0 | K40: 0 | L40: 0 | M40: 0 | N40: 0 | O40: 0 | P40: 0 | Q40: 0 | R40: 0 | S40: 0 | T40: 0 | U40: 0 | V40: 0 | W40: 0 | X40: 0 | Y40: 0 | Z40: 0 | AA40: 0 | AB40: 0 | AC40: 0 | AD40: 0 | AE40: 0 | AF40: 0 | AG40: 0 | AH40: 0 | AI40: 0 | AJ40: 0 | AK40: 0
D41: aluminium | E41: kg | F41: 0 | G41: 0 | J41: 0.1 | K41: 0 | L41: 0 | M41: 0 | N41: 0 | O41: 0 | P41: 0 | Q41: 0 | R41: 0 | S41: 0 | T41: 0 | U41: 0 | V41: 0 | W41: 0 | X41: 0 | Y41: 0 | Z41: 0 | AA41: 0 | AB41: 0 | AC41: 0 | AD41: 0 | AE41: 0 | AF41: 0 | AG41: 0 | AH41: 0 | AI41: 0 | AJ41: 0 | AK41: 0
D42: verre | E42: kg | F42: 0 | G42: 0 | J42: 0 | K42: 0 | L42: 0 | M42: 0 | N42: 0 | O42: 0 | P42: 0 | Q42: 0 | R42: 0 | S42: 0 | T42: 0 | U42: 0 | V42: 0 | W42: 0 | X42: 0 | Y42: 0 | Z42: 0 | AA42: 0 | AB42: 0 | AC42: 0 | AD42: 0 | AE42: 0 | AF42: 0 | AG42: 0 | AH42: 0 | AI42: 0 | AJ42: 0 | AK42: 0
D43: peinture | E43: kg | F43: 0 | G43: 0 | J43: 0 | K43: 0 | L43: 0 | M43: 0 | N43: 0 | O43: 0 | P43: 0 | Q43: 0 | R43: 0 | S43: 0 | T43: 0 | U43: 0 | V43: 0 | W43: 0 | X43: 0 | Y43: 0 | Z43: 0 | AA43: 0 | AB43: 0 | AC43: 0 | AD43: 0 | AE43: 0 | AF43: 0 | AG43: 0 | AH43: 0 | AI43: 0 | AJ43: 0 | AK43: 0
D44: plastiques | E44: kg | F44: 0 | G44: 0 | J44: 0.1 | K44: 0 | L44: 0 | M44: 0 | N44: 0 | O44: 0 | P44: 0 | Q44: 0 | R44: 0 | S44: 0 | T44: 0 | U44: 0 | V44: 0 | W44: 0 | X44: 0 | Y44: 0 | Z44: 0 | AA44: 0 | AB44: 0 | AC44: 0 | AD44: 0 | AE44: 0 | AF44: 0 | AG44: 0 | AH44: 0 | AI44: 0 | AJ44: 0 | AK44: 0
D45: gomme | E45: kg | F45: 0 | G45: 0 | J45: 0 | K45: 0 | L45: 0 | M45: 0 | N45: 0 | O45: 0 | P45: 0 | Q45: 0 | R45: 0 | S45: 0 | T45: 0 | U45: 0 | V45: 0 | W45: 0 | X45: 0 | Y45: 0 | Z45: 0 | AA45: 0 | AB45: 0 | AC45: 0 | AD45: 0 | AE45: 0 | AF45: 0 | AG45: 0 | AH45: 0 | AI45: 0 | AJ45: 0 | AK45: 0
D46: lubrifiant | E46: kg | F46: 0 | G46: 0 | J46: 0 | K46: 0 | L46: 0 | M46: 0 | N46: 0 | O46: 0 | P46: 0 | Q46: 0 | R46: 0 | S46: 0 | T46: 0 | U46: 0 | V46: 0 | W46: 0 | X46: 0 | Y46: 0 | Z46: 0 | AA46: 0 | AB46: 0 | AC46: 0 | AD46: 0 | AE46: 0 | AF46: 0 | AG46: 0 | AH46: 0 | AI46: 0 | AJ46: 0 | AK46: 0
D47: cuivre | E47: kg | F47: 0 | G47: 0 | J47: 0.5 | K47: 0 | L47: 0 | M47: 0 | N47: 0 | O47: 0 | P47: 0 | Q47: 0 | R47: 0 | S47: 0 | T47: 0 | U47: 0 | V47: 0 | W47: 0 | X47: 0 | Y47: 0 | Z47: 0 | AA47: 0 | AB47: 0 | AC47: 0 | AD47: 0 | AE47: 0 | AF47: 0 | AG47: 0 | AH47: 0 | AI47: 0 | AJ47: 0 | AK47: 0
...

Sheet Analyse d'impacts
C1: Résultats absolus | I1: Résultats relatifs | R1: Changement climatique (g CO2 eq.) | Y1: Énergie primaire (100 J) | AE1: Matériaux (μg Sb eq.)
C2: Changement climatique (g CO2 eq.) | E2: Énergie primaire (100 J) | G2: Matériaux (μg Sb eq.) | I2: Changement climatique | K2: Énergie primaire | M2: Matériaux
C3: transport, voiture diesel | D3: transport, voiture électrique | E3: transport, voiture diesel | F3: transport, voiture électrique | G3: transport, voiture diesel | H3: transport, voiture électrique | I3: transport, voiture diesel | J3: transport, voiture électrique | K3: transport, voiture diesel | L3: transport, voiture électrique | M3: transport, voiture diesel | N3: transport, voiture électrique | R3: transport, voiture diesel | S3: Allemagne 2020 | T3: France 2020 | U3: Allemagne 2040, tendanciel | V3: France 2040, tendanciel | W3: Allemagne 2040, optimiste | X3: France 2040, optimiste
C4: km | D4: km | E4: km | F4: km | G4: km | H4: km | I4: km | J4: km | K4: km | L4: km | M4: km | N4: km | R4: km | S4: km | T4: km | U4: km | V4: km | W4: km | X4: km
A5: activité | B5: unité
A6: transport, voiture diesel | B6: km | C6: {=Inventaire!$F$126:$G$157*TRANSPOSE(Inventaire!$F84:$AK84)*1000} -> #DIV/0! | D6: #DIV/0! | E6: {=Inventaire!$F$126:$G$157*TRANSPOSE(Inventaire!$F85:$AK85)*100} -> #DIV/0! | F6: #DIV/0! | G6: {=Inventaire!$F$126:$G$157*TRANSPOSE(Inventaire!$F86:$AK86)*1000000000} -> #DIV/0! | H6: #DIV/0! | I6: {=C6:D38/MAX(C38:D38)} -> #DIV/0! | J6: #DIV/0! | K6: {=E6:F38/MAX(E38:F38)} -> #DIV/0! | L6: #DIV/0! | M6: {=G6:H38/MAX(G38:H38)} -> #DIV/0! | N6: #DIV/0! | R6: 187 | S6: 0 | T6: 0 | U6: 0 | V6: 0 | W6: 0 | X6: 0
A7: transport, voiture électrique | B7: km | C7: #DIV/0! | D7: #DIV/0! | E7: #DIV/0! | F7: #DIV/0! | G7: #DIV/0! | H7: #DIV/0! | I7: #DIV/0! | J7: #DIV/0! | K7: #DIV/0! | L7: #DIV/0! | M7: #DIV/0! | N7: #DIV/0! | R7: 0 | S7: 0 | T7: 0 | U7: 0 | V7: 0 | W7: 0 | X7: 0
A8: voiture diesel | B8: u | C8: #DIV/0! | D8: #DIV/0! | E8: #DIV/0! | F8: #DIV/0! | G8: #DIV/0! | H8: #DIV/0! | I8: #DIV/0! | J8: #DIV/0! | K8: #DIV/0! | L8: #DIV/0! | M8: #DIV/0! | N8: #DIV/0! | R8: 0 | S8: 0 | T8: 0 | U8: 0 | V8: 0 | W8: 0 | X8: 0
A9: voiture électrique | B9: u | C9: #DIV/0! | D9: #DIV/0! | E9: #DIV/0! | F9: #DIV/0! | G9: #DIV/0! | H9: #DIV/0! | I9: #DIV/0! | J9: #DIV/0! | K9: #DIV/0! | L9: #DIV/0! | M9: #DIV/0! | N9: #DIV/0! | R9: 0 | S9: 0 | T9: 0 | U9: 0 | V9: 0 | W9: 0 | X9: 0
A10: batterie lithium-ion, production | B10: kWh | C10: #DIV/0! | D10: #DIV/0! | E10: #DIV/0! | F10: #DIV/0! | G10: #DIV/0! | H10: #DIV/0! | I10: #DIV/0! | J10: #DIV/0! | K10: #DIV/0! | L10: #DIV/0! | M10: #DIV/0! | N10: #DIV/0! | R10: 0 | S10: 17.2896 | T10: 17.2896 | U10: 17.2896 | V10: 17.2896 | W10: 17.2896 | X10: 17.2896
A11: batterie lithium-ion, recyclage | B11: kWh | C11: #DIV/0! | D11: #DIV/0! | E11: #DIV/0! | F11: #DIV/0! | G11: #DIV/0! | H11: #DIV/0! | I11: #DIV/0! | J11: #DIV/0! | K11: #DIV/0! | L11: #DIV/0! | M11: #DIV/0! | N11: #DIV/0! | R11: 0 | S11: -1.7472 | T11: -1.7472 | U11: -1.7472 | V11: -1.7472 | W11: -1.7472 | X11: -1.7472
A12: gazole | B12: l | C12: #DIV/0! | D12: #DIV/0! | E12: #DIV/0! | F12: #DIV/0! | G12: #DIV/0! | H12: #DIV/0! | I12: #DIV/0! | J12: #DIV/0! | K12: #DIV/0! | L12: #DIV/0! | M12: #DIV/0! | N12: #DIV/0! | R12: 41.3 | S12: 0 | T12: 0 | U12: 0 | V12: 0 | W12: 0 | X12: 0
A13: maintenance | B13: h | C13: #DIV/0! | D13: #DIV/0! | E13: #DIV/0! | F13: #DIV/0! | G13: #DIV/0! | H13: #DIV/0! | I13: #DIV/0! | J13: #DIV/0! | K13: #DIV/0! | L13: #DIV/0! | M13: #DIV/0! | N13: #DIV/0! | R13: 0.6 | S13: 0 | T13: 0 | U13: 0 | V13: 0 | W13: 0 | X13: 0
A14: acier | B14: kg | C14: #DIV/0! | D14: #DIV/0! | E14: #DIV/0! | F14: #DIV/0! | G14: #DIV/0! | H14: #DIV/0! | I14: #DIV/0! | J14: #DIV/0! | K14: #DIV/0! | L14: #DIV/0! | M14: #DIV/0! | N14: #DIV/0! | R14: 8.297224 | S14: 7.109648 | T14: 7.109648 | U14: 7.109648 | V14: 7.109648 | W14: 7.109648 | X14: 7.109648
A15: fonte | B15: kg | C15: #DIV/0! | D15: #DIV/0! | E15: #DIV/0! | F15: #DIV/0! | G15: #DIV/0! | H15: #DIV/0! | I15: #DIV/0! | J15: #DIV/0! | K15: #DIV/0! | L15: #DIV/0! | M15: #DIV/0! | N15: #DIV/0! | R15: 0.57528 | S15: 0.31104 | T15: 0.31104 | U15: 0.31104 | V15: 0.31104 | W15: 0.31104 | X15: 0.31104
A16: aluminium | B16: kg | C16: #DIV/0! | D16: #DIV/0! | E16: #DIV/0! | F16: #DIV/0! | G16: #DIV/0! | H16: #DIV/0! | I16: #DIV/0! | J16: #DIV/0! | K16: #DIV/0! | L16: #DIV/0! | M16: #DIV/0! | N16: #DIV/0! | R16: 9.75086 | S16: 12.70552 | T16: 12.70552 | U16: 12.70552 | V16: 12.70552 | W16: 12.70552 | X16: 12.70552
A17: verre | B17: kg | C17: #DIV/0! | D17: #DIV/0! | E17: #DIV/0! | F17: #DIV/0! | G17: #DIV/0! | H17: #DIV/0! | I17: #DIV/0! | J17: #DIV/0! | K17: #DIV/0! | L17: #DIV/0! | M17: #DIV/0! | N17: #DIV/0! | R17: 0.169048 | S17: 0.173568 | T17: 0.173568 | U17: 0.173568 | V17: 0.173568 | W17: 0.173568 | X17: 0.173568
A18: peinture | B18: kg | C18: #DIV/0! | D18: #DIV/0! | E18: #DIV/0! | F18: #DIV/0! | G18: #DIV/0! | H18: #DIV/0! | I18: #DIV/0! | J18: #DIV/0! | K18: #DIV/0! | L18: #DIV/0! | M18: #DIV/0! | N18: #DIV/0! | R18: 0.154496 | S18: 0.145408 | T18: 0.145408 | U18: 0.145408 | V18: 0.145408 | W18: 0.145408 | X18: 0.145408
... A37: chaleur | B37: MJ | C37: #DIV/0! | D37: #DIV/0! | E37: #DIV/0! | F37: #DIV/0! | G37: #DIV/0! | H37: #DIV/0! | I37: #DIV/0! | J37: #DIV/0! | K37: #DIV/0! | L37: #DIV/0! | M37: #DIV/0! | N37: #DIV/0! | R37: 0 | S37: 0 | T37: 0 | U37: 0 | V37: 0 | W37: 0 | X37: 0
A38: total | C38: =SUM(C6:C37) -> #DIV/0! | D38: =SUM(D6:D37) -> #DIV/0! | E38: =SUM(E6:E37) -> #DIV/0! | F38: =SUM(F6:F37) -> #DIV/0! | G38: =SUM(G6:G37) -> #DIV/0! | H38: =SUM(H6:H37) -> #DIV/0! | I38: #DIV/0! | J38: #DIV/0! | K38: #DIV/0! | L38: #DIV/0! | M38: #DIV/0! | N38: #DIV/0! | R38: 273.20148 | S38: 205.31688 | T38: 87.086707 | U38: 158.48685 | V38: 77.556821 | W38: 99.710101 | X38: 79.168078

Sheet Composition voiture
B1: Composition | D1: Facteurs
A2: Élément | B2: Voiture thermique | C2: Voiture électrique (hors batterie) | D2: GES (g CO2 eq./kg) | E2: Énergie primaire (kWh/kg) | G2: https://www.greenncap.com/wp-content/uploads/Green-NCAP-Life-Cycle-Assessment-Methodology-and-Data.pdf
A3: Acier | B3: 0.494 | C3: 0.446 | D3: 2470 | E3: 8.9
A4: Fonte | B4: 0.094 | C4: 0.054 | D4: 900 | E4: 3.5
A5: Aluminium | B5: 0.119 | C5: 0.161 | D5: 12050 | E5: 53.2
A6: Verre | B6: 0.022 | C6: 0.024 | D6: 1130 | E6: 3.3
A7: Peinture | B7: 0.004 | C7: 0.004 | D7: 5680 | E7: 28
A8: Plastiques | B8: 0.11 | C8: 0.116 | D8: 3610 | E8: 8.6
A9: Gomme | B9: 0.037 | C9: 0.04 | D9: 3300 | E9: 9.9
A10: Lubrifiant | B10: 0.009 | C10: 0.004 | D10: 4200 | E10: 13.3
A11: Cuivre | B11: 0.023 | C11: 0.037 | D11: 3610 | E11: 11.9
A12: Métaux non ferreux | B12: 0.004 | C12: 0.016 | D12: 7670 | E12: 30.3
A13: Électronique | B13: 0.047 | C13: 0.057 | D13: 36630 | E13: 133.4
A14: Textiles | B14: 0.037 | C14: 0.041 | D14: 24250 | E14: 75.2
A15: Fibre de carbone | B15: 0 | C15: 0 | D15: 18940 | E15: 90.2

Sheet Production batterie
A1: Batterie lithium-ion | B1: CO2 | C1: CH4 | D1: Énergie primaire
A2: Production | K2: https://www.greenncap.com/wp-content/uploads/Green-NCAP-Life-Cycle-Assessment-Methodology-and-Data.pdf
A3: Chine | B3: 112 | C3: 0.23 | D3: 440
A4: EU | B4: 67 | C4: 0.18 | D4: 387
A5: US | B5: 81 | C5: 0.2 | D5: 426
A6: Recyclage
A7: Chine | B7: -22 | C7: -0.02 | D7: -86
A8: EU | B8: -7 | C8: -0.01 | D8: -62
A9: US | B9: -10 | C9: -0.01 | D9: -68

Sheet Mix électriques
B1: France, scénario tendanciel, 2020 | C1: France, scénario tendanciel, 2030 | D1: France, scénario tendanciel, 2040 | E1: France, scénario tendanciel, 2050 | F1: Allemagne, scénario tendanciel, 2020 | G1: Allemagne, scénario tendanciel, 2030 | H1: Allemagne, scénario tendanciel, 2040 | I1: Allemagne, scénario tendanciel, 2050 | J1: France, scénario optimiste, 2020 | K1: France, scénario optimiste, 2030 | L1: France, scénario optimiste, 2040 | M1: France, scénario optimiste, 2050 | N1: Allemagne, scénario optimiste, 2020 | O1: Allemagne, scénario optimiste, 2030 | P1: Allemagne, scénario optimiste, 2040 | Q1: Allemagne, scénario optimiste, 2050
A2: électricité nucléaire | B2: 0.65649653 | C2: 0.54302148 | D2: 0.37480404 | E2: 0.30955166 | F2: 0.058795405 | G2: 0 | H2: 0 | I2: 0 | J2: 0.65567467 | K2: 0.54382914 | L2: 0.35114706 | M2: 0.24625419 | N2: 0.05881405 | O2: 0 | P2: 0 | Q2: 0
A3: électricité éolienne | B3: 0.095258761 | C3: 0.18715832 | D3: 0.37401154 | E3: 0.41201528 | F3: 0.18816348 | G3: 0.34638042 | H3: 0.43123084 | I3: 0.50888587 | J3: 0.095140197 | K3: 0.18994189 | L3: 0.39954077 | M3: 0.45334735 | N3: 0.18823765 | O3: 0.34483683 | P3: 0.67249259 | Q3: 0.63654196
A4: électricité photovoltaïque | B4: 0.046130916 | C4: 0.1016366 | D4: 0.10835594 | E4: 0.14014257 | F4: 0.081287261 | G4: 0.1390007 | H4: 0.14508287 | I4: 0.18217663 | J4: 0.046073362 | K4: 0.10270248 | L4: 0.11405616 | M4: 0.15111115 | N4: 0.081314058 | O4: 0.13848321 | P4: 0.17379573 | Q4: 0.20232728
A5: électricité hydroélectrique | B5: 0.11623471 | C5: 0.10562885 | D5: 0.10112369 | E5: 0.092076369 | F5: 0.040684209 | G5: 0.039818609 | H5: 0.040588438 | I5: 0.039058781 | J5: 0.11608919 | K5: 0.10693857 | L5: 0.085191752 | M5: 0.063720604 | N5: 0.040496353 | O5: 0.040020303 | P5: 0.030612358 | Q5: 0.023958973
A6: électricité au charbon | B6: 0.014602928 | C6: 0 | D6: 0 | E6: 0 | F6: 0.44998135 | G6: 0.26747299 | H6: 0.1069755 | I6: 0.010621272 | J6: 0.014584647 | K6: 0 | L6: 0 | M6: 0 | N6: 0.4483675 | O6: 0.26878753 | P6: 0.0044776469 | Q6: 0
A7: électricité au gaz | B7: 0.04760145 | C7: 0.018049436 | D7: 0.0096778052 | E7: 0.0075678832 | F7: 0.12928178 | G7: 0.1207001 | H7: 0.17495794 | I7: 0.1569316 | J7: 0.048792905 | K7: 0.011975048 | L7: 0.0053683478 | M7: 0.006037668 | N7: 0.12719069 | O7: 0.11656797 | P7: 0.025852939 | Q7: 0.00057065687
A8: électricité, autre | B8: 0.023674704 | C8: 0.044505318 | D8: 0.032026984 | E8: 0.03864623 | F8: 0.051806518 | G8: 0.086627182 | H8: 0.10116441 | I8: 0.10232586 | J8: 0.023645022 | K8: 0.044612875 | L8: 0.044695908 | M8: 0.079529034 | N8: 0.055579707 | O8: 0.091304157 | P8: 0.092768738 | Q8: 0.13660113
A10: Source | B10: https://climate.ec.europa.eu/system/files/2020-09/2020_study_main_report_en.pdf

Sheet Carburant
